<robot name="urdf_robot">

  <link name="base_link" xmlns:xacro="http://ros.org/wiki/xacro">
    <visual>
      <geometry>
        <box size="0.15 0.15 0.15"/>
      </geometry>
      <origin rpy="0 0 0" xyz="0 0 0"/>
      <material name="white">
        <color rgba="1 1 1 1"/>
      </material>
    </visual>

    <collision>
      <origin rpy="0 0 0" xyz="0 0 0"/>
      <geometry>
        <box size="0.15 0.15 0.15"/>
      </geometry>
    </collision>

    <inertial>
      <origin rpy="0 0 0" xyz="0 0 0"/>
      <mass value="0.1"/>
      <inertia ixx="0.16666666666"  ixy="0"  ixz="0" iyy="0.16666666666" iyz="0" izz="0.16666666666" />
    </inertial>

  </link>

  <link name="left_wheel">
    <visual>
      <geometry>
        <cylinder length="0.02" radius="0.15"/>
      </geometry>
      <origin rpy="0 0 0" xyz="0 0 0"/>
      <material name="black">
        <color rgba="0 0 0 1"/>
      </material>
    </visual>

    <collision>
      <origin rpy="0 0 0" xyz="0 0 0"/>
      <geometry>
        <cylinder length="0.02" radius="0.15"/>
      </geometry>
    </collision>

    <inertial>
      <origin rpy="0 0 0" xyz="0 0 0"/>
      <mass value="0.025"/>
      <!-- {{0.00575833, 0, 0}, {0, 0.00575833, 0}, {0, 0, 0.01125}} -->
      <inertia ixx="0.00575833"  ixy="0"  ixz="0" iyy="0.00575833" iyz="0" izz="0.01125" />
    </inertial>
  </link>

  <joint name="base_to_left_wheel" type="continuous">
    <parent link="base_link"/>
    <child link="left_wheel"/>
    <origin rpy="-1.5708 0 0" xyz="0 0.1 0"/>
    <axis xyz="0 0 1"/>
  </joint>

  <transmission name="left_wheel_transmission">
    <type>transmission_interface/SimpleTransmission</type>
    <joint name="base_to_left_wheel">
      <hardwareInterface>hardware_interface/VelocityJointInterface</hardwareInterface>
    </joint>
    <actuator name="left_wheel_actuator">
      <mechanicalReduction>1</mechanicalReduction>
    </actuator>
	</transmission>





  <link name="right_wheel">
    <visual>
      <geometry>
        <cylinder length="0.02" radius="0.15"/>
      </geometry>
      <origin rpy="0 0 0" xyz="0 0 0"/>
      <material name="black">
        <color rgba="0 0 0 1"/>
      </material>
    </visual>

    <collision>
      <origin rpy="0 0 0" xyz="0 0 0"/>
      <geometry>
        <cylinder length="0.02" radius="0.15"/>
      </geometry>
    </collision>

    <inertial>
      <origin rpy="0 0 0" xyz="0 0 0"/>
      <mass value="0.025"/>
      <!-- {{0.00575833, 0, 0}, {0, 0.00575833, 0}, {0, 0, 0.01125}} -->
      <inertia ixx="0.00575833"  ixy="0"  ixz="0" iyy="0.00575833" iyz="0" izz="0.01125" />
    </inertial>
  </link>

  <joint name="base_to_right_wheel" type="continuous">
    <parent link="base_link"/>
    <child link="right_wheel"/>
    <origin rpy="-1.5708 0 0" xyz="0 -0.1 0"/>
    <axis xyz="0 0 1"/>
  </joint>

  <transmission name="right_wheel_transmission">
    <type>transmission_interface/SimpleTransmission</type>
    <joint name="base_to_right_wheel">
      <hardwareInterface>hardware_interface/VelocityJointInterface</hardwareInterface>
    </joint>
    <actuator name="right_wheel_actuator">
      <mechanicalReduction>1</mechanicalReduction>
    </actuator>
	</transmission>


  <gazebo reference="right_wheel">
    <mu1 value="100000.0"/>
    <mu2 value="100.0"/>
    <kp  value="10000000.0" />
    <kd  value="1.0" />
    <fdir1 value="1 0 0"/>
    <turnGravityOff>false</turnGravityOff>
  </gazebo>

  <gazebo reference="left_wheel">
    <mu1 value="100000.0"/>
    <mu2 value="100.0"/>
    <kp  value="10000000.0" />
    <kd  value="1.0" />
    <fdir1 value="1 0 0"/>
    <turnGravityOff>false</turnGravityOff>
  </gazebo>

  <!-- <gazebo>
    <plugin name="gazebo_ros_control" filename="libgazebo_ros_diff_drive.so">
      <robotNamespace>/</robotNamespace>
      <legacyModeNS>true</legacyModeNS>
      <alwaysOn>true</alwaysOn>
    <legacyMode>false</legacyMode>
    <updateRate>40</updateRate>
    <leftJoint>base_to_left_wheel</leftJoint>
    <rightJoint>base_to_right_wheel</rightJoint>
    <wheelSeparation>0.2</wheelSeparation>
    <wheelDiameter>0.15</wheelDiameter>
    <torque>20</torque>
    <commandTopic>cmd_vel</commandTopic>
    <odometryTopic>odom</odometryTopic>
    <odometryFrame>odom</odometryFrame>
    <publishWheelTF>true</publishWheelTF>
    <publishOdomTF>true</publishOdomTF>
    <publishWheelJointState>true</publishWheelJointState>
    <robotBaseFrame>base_link</robotBaseFrame>
    </plugin>
  </gazebo> -->

  <gazebo>
    <plugin name="gazebo_ros_control" filename="libgazebo_ros_control.so">
      <robotNamespace>/</robotNamespace>
      <legacyModeNS>true</legacyModeNS>
      <legacyMode>false</legacyMode>
    </plugin>
  </gazebo>


</robot>